Workbook

Sheet FORMULAS
A1: MUJER | D1: HOMBRE
A2: Peso kg | B2: =MUJER!B2 -> 82 | D2: Peso kg | E2: =HOMBRE!B2 -> 85 | G2: NOTA: DEPENDIENDO DE MB CAMBIAR LA CELDA
A3: Talla | B3: =MUJER!B3 -> 160 | D3: Talla | E3: =HOMBRE!B3 -> 170
A4: IMC | B4: =MUJER!B4 -> 32.03125 | D4: IMC | E4: =HOMBRE!B4 -> 29.411765 | L4: Cotenido nutricional de la porción de intercambio
A5: Edad | B5: =MUJER!B5 -> 42 | D5: Edad | E5: =HOMBRE!B5 -> 45 | L5: Grupo de alimento | P5: CHO (g) | Q5: Prot (g) | R5: Grasas (g)
L6: Cereales, tuberculos y plátanos | O6: Altos en CHO y bajos en grasas | P6: 30 | Q6: 4 | R6: 1
A7: REE | O7: Medios en CHO y bajos en grasas | P7: 20 | Q7: 3 | R7: 1
A8: Formulas | B8: Mujer | C8: Hombre | O8: Medios en CHO y medios en grasas | P8: 20 | Q8: 2 | R8: 6
A9: owen | B9: =795+(7.18*B2) -> 1383.76 | C9: =879+(10.2*E2) -> 1746 | E9: ACTIVIDAD FÍSICA | H9: GET -- Oxford y OMS | L9: Frutas | O9: Medias en CHO | P9: 20 | Q9: 1 | R9: 0
A10: valencia | B10: =(11.02*B2)+679 -> 1582.64 | C10: =(14.21*E2)+429 -> 1636.85 | E10: Sedentario | F10: 1.2 | H10: Mujer | I10: =(B24*F15)+(B24/10) -> 2021.24 | O10: Bajas en CHO | P10: 10 | Q10: 1 | R10: 0
A11: mifflin | B11: =(10*B2)+(6.25*B3)-(5*B5)-161 -> 1449 | C11: =(10*E2)+(6.25*E3)-(5*E5)+5 -> 1692.5 | E11: Activo | F11: 1.5 | H11: Hombre | I11: =(C25*F15)+(C25/10) -> 2277.21 | O11: Deshidratadas | P11: 20 | Q11: 1 | R11: 0
A12: harris & b | B12: =655.0955+(9.5634*B2)+(1.8449*B3)-(4.6756*B5) -> 1538.1031 | C12: =66.473+(13.7516*E2)+(5.0033*E3)-(6.775*E5) -> 1781.045 | E12: Muy activo | F12: 1.725 | L12: Vegetales | O12: Bajos en CHO | P12: 5 | Q12: 1 | R12: 0
A13: cunnigham | B13: =(500+22*B19) -> 1660.7777 | C13: =(500+22*C19) -> 1411.4492 | E13: Otro | F13: 0 | H13: GET | O13: Libre consumo | P13: 3 | Q13: 2 | R13: 0
A14: livingston | B14: =248*(B2^0.43356)-B5*5.09 -> 1461.953 | C14: =293*(E2^0.433)-E5*5.92 -> 1739.4849 | H14: Mujer | I14: =MUJER!B10 -> mifflin | J14: =((VLOOKUP(I14,$A$9:$B$15,2,FALSE))*$F$15)+(VLOOKUP(I14,$A$9:$B$15,2,FALSE)*10%) -> 1883.7 | L14: Lacteos | O14: Enteros - altos en grasas | P14: 11 | Q14: 8 | R14: 8
A15: estimación rápida | B15: =16.2*B2 -> 1328.4 | C15: =17*E2 -> 1445 | E15: TA | F15: 1.2 | H15: Hombre | I15: =HOMBRE!B10 -> mifflin | J15: =((VLOOKUP(I15,$A$9:$C$15,3,FALSE))*$F$15)+(VLOOKUP(I15,$A$9:$C$15,3,FALSE)*10%) -> 2200.25 | O15: Semidescremados - medios en grasas | P15: 11 | Q15: 8 | R15: 4
O16: Descremados - bajos en grasas | P16: 12 | Q16: 8 | R16: 1
O17: Descremados y altos en CHO | P17: 25 | Q17: 6 | R17: 3
B18: Mujer | C18: Hombre | E18: C BRAZO | F18: c CINTURA | G18: C pantorilla | H18: formula | O18: Quesos | P18: 1 | Q18: 7 | R18: 7
A19: LBM (cunnigham) | B19: =(79.5-(0.24*(B2))-(0.15*(B5))*B2/73.2) -> 52.762623 | C19: =(69.8-(0.26*E2)-(0.12*E5)*E2/73.2) -> 41.429508 | E19: 32 | F19: 102 | G19: 40 | H19: =(0.5759*E19)+(0.5263*F19)+(1.2452*G19)-37.793 -> 84.1264 | L19: Carnes, pescados y huevos | O19: Altos en grasas | P19: 1 | Q19: 11 | R19: 15
O20: Medios en grasas | P20: 0 | Q20: 11 | R20: 7
A21: Formula de oxford | O21: Bajos en grasas | P21: 0 | Q21: 11 | R21: 2
B22: Mujer | C22: Hombre | E22: Distribucción energética | G22: Proteína g/kg/día | I22: DISTRIBUCION DE ALIMENTOS | O22: Embutidos | P22: 1 | Q22: 7 | R22: 7
A23: 10-18 años | B23: =(9.4*$B$2)+246*($B$3*0.01)+462 -> 1626.4 | C23: =(15.6*$E$2)+266*($E$3*0.01)+299 -> 2077.2 | E23: CHO | F23: 55-60% | G23: Hipoproteico (g) | H23: 1 | I23: PRIMER | J23: CEREALES 50% CHO | L23: Leguminosas | O23: Leguminosas | P23: 20 | Q23: 9 | R23: 1
A24: 18-30 | B24: =(10.4*$B$2)+615*($B$3*0.01)-282 -> 1554.8 | C24: =(14.4*$E$2)+313*($E$3*0.01)+113 -> 1869.1 | E24: Proteínas | F24: 10-15% | G24: Normoproteico (g) | H24: 1.2 | I24: SEGUNDO | J24: PROTEINAS | L24: Grasas y frutos secos | O24: Altos en grasas | P24: 1 | Q24: 1 | R24: 12
A25: 30-60 | B25: =(8.18*$B$2)+502*($B$3*0.01)-11.6 -> 1462.36 | C25: =(11.4*$E$2)+541*($E$3*0.01)-137 -> 1751.7 | E25: Grasas | F25: 25-35% | G25: Hiperproteico (g) | H25: 1.5 | I25: TERCERO | J25: GRASAS | O25: Medios en grasas | P25: 2 | Q25: 1 | R25: 7
A26: >60 | B26: =(8.52*$B$2)+421*($B$3*0.01)-10.7 -> 1361.54 | C26: =(11.4*$E$2)+541*($E$3*0.01)-256 -> 1632.7 | G26: Otro | I26: CUARTO | J26: CHO FALTANTES | O26: Altos en grasas y bajos en CHO | P26: 8 | Q26: 4 | R26: 10
O27: Medios en grasas y bajor en CHO | P27: 12 | Q27: 2 | R27: 7
A28: FAO/OMS | L28: Azucares y alimentos azucarados | O28: Azucares y alimentos azucarados | P28: 10 | Q28: 0 | R28: 0
B29: Mujer | C29: Hombre
A30: 0-3 años | B30: =(61*$B$2)-51 -> 4951 | C30: =(60.9*$E$2)-54 -> 5122.5
A31: 4-10 años | B31: =(22.5*$B$2)+499 -> 2344 | C31: =(22.7*$E$2)+495 -> 2424.5
A32: 11-18 años | B32: =(12.2*$B$2)+746 -> 1746.4 | C32: =(17.5*$E$2)+651 -> 2138.5
A33: 19-30 años | B33: =(14.7*$B$2)+496 -> 1701.4 | C33: =(15.3*$E$2)+679 -> 1979.5
A34: 31-60 años | B34: =(8.7*$B$2)+829 -> 1542.4 | C34: =(11.6*$E$2)+879 -> 1865
A35: >60 | B35: =(10.5*$B$2)+596 -> 1457 | C35: =(13.5*$E$2)+487 -> 1634.5
A38: Hipoproteico (g) | B38: Normoproteico (g) | C38: Hiperproteico (g)
A39: 0.8 | B39: 1 | C39: 1.3
A40: 0.9 | B40: 1.1 | C40: 1.4
A41: 1 | B41: 1.2 | C41: 1.5
C42: 1.6
...

Sheet TCA
A1: Grupo | B1: Alimento | C1: 100 | D1: Nombre en Inglés | E1: Energía calculada (Kcal) | F1: Proteína (g) | G1: Grasa total (g) | H1: Carbohidratos (g) | I1: Fibra (g) | J1: AGS (g) | K1: AGM (g) | L1: AGPI (g) | M1: Colesterol (mg) | N1: Calcio (mg) | O1: Fósforo (mg) | P1: Hierro (mg) | Q1: Potasio (mg) | R1: Sodio (mg) | S1: Zinc (mg) | T1: Vitamina C (mg) | U1: Vitamina A (µg ERE) | V1: Folatos (µg) | W1: Vitamina B12 (µg)
A3: Cereales | B3: Amaranto, grano seco | D3: Amaranth, grain, dry, uncooked | E3: 381.07 | F3: 14.45 | G3: 6.51 | H3: 66.17 | I3: 9.3 | J3: 1.66 | K3: 1.43 | L3: 2.89 | M3: 0 | N3: 153 | O3: 455 | P3: 7.59 | Q3: 366 | R3: 21 | S3: 3.18 | T3: 4 | U3: 0 | V3: 49 | W3: 0
A4: Cereales | B4: Arroz blanco grano largo, cocido | D4: Rice, white, long-grain, unenriched, cooked, with salt | E4: 125.96 | F4: 2.69 | G4: 0.28 | H4: 28.17 | I4: 0.4 | J4: 0.08 | K4: 0.09 | L4: 0.08 | M4: 0 | N4: 10 | O4: 43 | P4: 0.2 | Q4: 35 | R4: 382 | S4: 0.49 | T4: 0 | U4: 0 | V4: 3 | W4: 0
A5: Cereales | B5: Arroz blanco, grano corto | D5: Rice, white, short-grain, unenriched, raw | E5: 347.28 | F5: 6.5 | G5: 0.52 | H5: 79.15 | J5: 0.14 | K5: 0.16 | L5: 0.14 | M5: 0 | N5: 3 | O5: 95 | P5: 0.8 | Q5: 76 | R5: 1 | S5: 1.1 | T5: 0 | V5: 6 | W5: 0
A6: Cereales | B6: Arroz blanco, grano corto, cocido | D6: Rice, white, short-grain, unenriched, cooked | E6: 126.07 | F6: 2.36 | G6: 0.19 | H6: 28.73 | J6: 0.05 | K6: 0.06 | L6: 0.05 | M6: 0 | N6: 1 | O6: 33 | P6: 0.2 | Q6: 26 | R6: 0 | S6: 0.4 | T6: 0 | V6: 2 | W6: 0
A7: Cereales | B7: Arroz blanco, grano largo crudo | D7: Rice, white, long-grain, raw, unenriched | E7: 354.26 | F7: 7.13 | G7: 0.66 | H7: 79.95 | I7: 1.3 | J7: 0.18 | K7: 0.21 | L7: 0.18 | M7: 0 | N7: 28 | O7: 115 | P7: 0.8 | Q7: 115 | R7: 5 | S7: 1.09 | T7: 0 | U7: 0 | V7: 8 | W7: 0
A8: Cereales | B8: Arroz blanco, grano largo, parbolizado, cocido | D8: Rice, white, long-grain, parabolized, unenriched, cooked | E8: 119.17 | F8: 2.91 | G8: 0.37 | H8: 26.05 | I8: 0.9 | J8: 0.07 | K8: 0.07 | L8: 0.09 | M8: 0 | N8: 19 | O8: 55 | P8: 0.24 | Q8: 56 | R8: 2 | S8: 0.37 | T8: 0 | V8: 3 | W8: 0
A9: Cereales | B9: Arroz blanco, grano largo, parbolizado, crudo | D9: Rice, white, long-grain, parabolized, unenriched, dry | E9: 362.87 | F9: 7.51 | G9: 1.03 | H9: 80.89 | I9: 1.8 | J9: 0.29 | K9: 0.26 | L9: 0.32 | M9: 0 | N9: 71 | O9: 153 | P9: 0.74 | Q9: 174 | R9: 2 | S9: 1.02 | T9: 0 | U9: 0 | V9: 8 | W9: 0
A10: Cereales | B10: Arroz blanco, grano medio, cocido | D10: Rice, white, medium-grain, unenriched, cooked | E10: 125.77 | F10: 2.38 | G10: 0.21 | H10: 28.59 | J10: 0.06 | K10: 0.07 | L10: 0.06 | M10: 0 | N10: 3 | O10: 37 | P10: 0.2 | Q10: 29 | R10: 0 | S10: 0.42 | T10: 0 | V10: 2 | W10: 0
A11: Cereales | B11: Arroz blanco, grano medio, crudo | D11: Rice, white, medium-grain, unenriched, raw | E11: 349.02 | F11: 6.61 | G11: 0.58 | H11: 79.34 | J11: 0.16 | K11: 0.18 | L11: 0.16 | M11: 0 | N11: 9 | O11: 108 | P11: 0.8 | Q11: 86 | R11: 1 | S11: 1.16 | T11: 0 | V11: 9 | W11: 0
A12: Cereales | B12: Arroz blanco, pulido, enriquecido,precocido | D12: Rice, white, long-grain, precooked, enriched, dry | E12: 369.02 | F12: 7.82 | G12: 0.94 | H12: 82.32 | I12: 1.9 | J12: 0.15 | K12: 0.14 | L12: 0.22 | M12: 0 | N12: 22 | O12: 118 | P12: 6.3 | Q12: 27 | R12: 10 | S12: 1.43 | T12: 0 | U12: 0 | V12: 466 | W12: 0
A13: Cereales | B13: Arroz integral, grano largo cocido | D13: Rice, brown, long-grain, cooked | E13: 122.01 | F13: 2.74 | G13: 0.97 | H13: 25.58 | I13: 1.6 | J13: 0.26 | K13: 0.37 | L13: 0.37 | M13: 0 | N13: 3 | O13: 103 | P13: 0.56 | Q13: 86 | R13: 4 | S13: 0.71 | T13: 0 | U13: 0 | V13: 9 | W13: 0
A14: Cereales | B14: Arroz integral, grano largo crudo | D14: Rice, brown, long-grain, raw | E14: 363.96 | F14: 7.54 | G14: 3.2 | H14: 76.25 | I14: 3.6 | J14: 0.59 | K14: 1.05 | L14: 1 | M14: 0 | N14: 9 | O14: 311 | P14: 1.29 | Q14: 250 | R14: 5 | S14: 2.13 | T14: 0 | U14: 0 | V14: 23 | W14: 0
A15: Cereales | B15: Arroz integral, grano medio, cocido | D15: Rice, brown, medium-grain, cooked | E15: 110.79 | F15: 2.32 | G15: 0.83 | H15: 23.51 | I15: 1.8 | J15: 0.17 | K15: 0.3 | L15: 0.3 | M15: 0 | N15: 10 | O15: 77 | P15: 0.53 | Q15: 79 | R15: 1 | S15: 0.62 | T15: 0 | U15: 0 | V15: 4 | W15: 0
A16: Cereales | B16: Arroz integral, grano medio, crudo | D16: Rice, brown, medium-grain, raw | E16: 358.8 | F16: 7.5 | G16: 2.68 | H16: 76.17 | I16: 3.4 | J16: 0.54 | K16: 0.97 | L16: 0.96 | M16: 0 | N16: 33 | O16: 264 | P16: 1.8 | Q16: 268 | R16: 4 | S16: 2.02 | T16: 0 | U16: 0 | V16: 20 | W16: 0
A17: Cereales | B17: Arroz precocido, eriquecido, crudo | D17: Rice, white, long-grain, precooked or instant, enriched, dry | E17: 369.02 | F17: 7.82 | G17: 0.94 | H17: 82.32 | I17: 1.9 | J17: 0.15 | K17: 0.14 | L17: 0.22 | M17: 0 | N17: 22 | O17: 118 | P17: 6.3 | Q17: 27 | R17: 10 | S17: 1.43 | T17: 0 | U17: 0 | V17: 275 | W17: 0
A18: Cereales | B18: Arroz, tipo arrocillo, crudo | D18: Rice, arrocillo type, raw | E18: 354.26 | F18: 7.13 | G18: 0.66 | H18: 79.95 | I18: 1.3 | J18: 0.18 | K18: 0.21 | L18: 0.18 | M18: 0 | N18: 28 | O18: 115 | P18: 0.8 | Q18: 115 | R18: 5 | S18: 1.09 | T18: 0 | U18: 0 | V18: 8 | W18: 0
A19: Cereales | B19: Avena, hojuelas, sin fortificar, Mosh | D19: Oats (flakes), unenriched, Mosh | E19: 394.74 | F19: 16.89 | G19: 6.9 | H19: 66.27 | I19: 10.6 | J19: 1.22 | K19: 2.18 | L19: 2.54 | M19: 0 | N19: 54 | O19: 523 | P19: 4.72 | Q19: 429 | R19: 2 | S19: 3.97 | T19: 0 | U19: 0 | V19: 56 | W19: 0
A20: Cereales | B20: Avena, molida, Quaker | D20: Oats, ground, Quaker | E20: 372.9 | F20: 15.5 | G20: 6.1 | H20: 64 | I20: 10.9 | J20: 1.08 | K20: 1.92 | L20: 2.23 | M20: 0 | N20: 357 | O20: 357 | P20: 28.93 | Q20: 354 | R20: 286 | S20: 3.07 | T20: 0 | U20: 1072 | V20: 464 | W20: 0
A21: Cereales | B21: Brazo gitano, relleno de dulce, promedio | D21: Swiss roll, wheat flour, eggs, butter, sweet filling, commercially prepared | E21: 231.58 | F21: 3.99 | G21: 8.18 | H21: 35.5 | N21: 18 | O21: 92 | P21: 0.59 | Q21: 67 | R21: 178 | S21: 0.35
A22: Cereales | B22: Cebada perlada | D22: Barley, pearled, raw | E22: 360.96 | F22: 9.91 | G22: 1.16 | H22: 77.72 | I22: 15.6 | J22: 0.24 | K22: 0.15 | L22: 0.56 | M22: 0 | N22: 29 | O22: 221 | P22: 2.5 | Q22: 280 | R22: 9 | S22: 213 | T22: 0 | U22: 1 | V22: 23 | W22: 0
A23: Cereales | B23: Cebada, arroz de cebada, cruda | D23: Barley rice, raw | E23: 364.54 | F23: 12.48 | G23: 2.3 | H23: 73.48 | I23: 17.3 | J23: 0.48 | K23: 0.29 | L23: 1.11 | M23: 0 | N23: 33 | O23: 264 | P23: 3.6 | Q23: 452 | R23: 12 | S23: 2.77 | T23: 0 | U23: 1 | V23: 19 | W23: 0
A24: Cereales | B24: Cebada, perlada, grano entero | D24: Barley, hulled, whole grain | E24: 364.54 | F24: 12.48 | G24: 2.3 | H24: 73.48 | I24: 17.3 | J24: 0.48 | K24: 0.29 | L24: 1.11 | M24: 0 | N24: 33 | O24: 264 | P24: 3.6 | Q24: 452 | R24: 12 | S24: 2.77 | T24: 0 | U24: 1 | V24: 19 | W24: 0
A25: Cereales | B25: Cebada, tapioca, perlada, seca | D25: Barley flour, tapioca, pearl,raw | E25: 355.7 | F25: 0.19 | G25: 0.02 | H25: 88.69 | I25: 0.9 | J25: 0 | K25: 0 | L25: 0 | M25: 0 | N25: 20 | O25: 7 | P25: 1.58 | Q25: 11 | R25: 1 | S25: 0.12 | T25: 0 | U25: 0 | V25: 4 | W25: 0
A26: Cereales | B26: Centeno, grano, crudo | D26: Rye, grain, raw | E26: 360.58 | F26: 14.76 | G26: 2.5 | H26: 69.76 | I26: 14.6 | J26: 0.29 | K26: 0.3 | L26: 1.12 | M26: 0 | N26: 33 | O26: 374 | P26: 2.67 | Q26: 264 | R26: 6 | S26: 3.73 | T26: 0 | U26: 1 | V26: 60 | W26: 0
A27: Cereales | B27: Cereal desayuno, amaranto, horneado, Nutrial | D27: Cereal, breakfast, baked amaranth, Nutrial | E27: 404.55 | F27: 13.64 | G27: 4.55 | H27: 77.27 | J27: 0 | K27: 0 | L27: 0 | M27: 0 | R27: 68.18
A28: Cereales | B28: Cereal desayuno, arroz crocante | D28: Cereal, breakfast, crispy rice | E28: 391.46 | F28: 7.32 | G28: 1.22 | H28: 87.8 | I28: 0 | J28: 0 | M28: 0 | N28: 0 | O28: 98 | P28: 30.73 | Q28: 98 | R28: 585 | S28: 18.29 | T28: 14.6 | U28: 731.7 | V28: 878 | W28: 8.78
A29: Cereales | B29: Cereal desayuno, arroz crocante | D29: Cereal, Breakfast, Kellogg´s, corn pops | E29: 389.7 | F29: 4.8 | G29: 1.3 | H29: 89.7 | I29: 8.4 | J29: 0.5 | K29: 0.2 | L29: 0.5 | M29: 0 | N29: 7 | O29: 52 | P29: 6 | Q29: 113 | R29: 357 | S29: 5 | T29: 20 | U29: 467 | V29: 333 | W29: 5
A30: Cereales | B30: Cereal desayuno, arroz crocante sabor a chocolate | D30: Cereal, breakfast, crispy rice, chocolate flavor | E30: 389.97 | F30: 3.33 | G30: 3.33 | H30: 86.67 | I30: 1.7 | J30: 0 | M30: 0 | N30: 0 | P30: 6 | R30: 300 | S30: 5 | T30: 0 | U30: 500.1 | W30: 2
A31: Cereales | B31: Cereal desayuno, con pasas, Kellog’s | D31: Cereal, breakfast, raisin bran, Kellogg’s | E31: 364.52 | F31: 7.72 | G31: 2.72 | H31: 77.29 | I31: 11.4 | J31: 0.48 | K31: 0.34 | L31: 0.95 | M31: 0 | N31: 43 | O31: 347 | P31: 12.33 | Q31: 653 | R31: 356 | S31: 3.39 | T31: 0 | U31: 386 | V31: 201 | W31: 19
A32: Cereales | B32: Cereal desayuno, corn flakes con miel, Kellog’s | D32: Cereal, breakfast, honey crunch corn flakes, Kellogg’s | E32: 392.3 | F32: 6.8 | G32: 1.9 | H32: 87 | I32: 3.4 | J32: 0.3 | K32: 1 | L32: 0.6 | M32: 0 | N32: 22 | O32: 60 | P32: 6.2 | Q32: 102 | R32: 700 | S32: 0.3 | T32: 20 | U32: 502 | V32: 553 | W32: 5
A33: Cereales | B33: Cereal desayuno, de arroz, con quinoa y chia, sabor a chile, Livekuna | D33: Cereal, breakfast, from rice, with quinua and chia, chile flavour, Livekuna | E33: 448.57 | F33: 8.57 | G33: 14.29 | H33: 71.43 | I33: 2.86 | J33: 2.86 | K33: 4.29 | L33: 8.57 | M33: 0 | R33: 514.29
A34: Cereales | B34: Cereal desayuno, froot loops, trix, Kellog’s | D34: Cereal, breakfast, froot loops, trix, Kellogg’s | E34: 397.98 | F34: 5.04 | G34: 3.1 | H34: 87.48 | I34: 2.5 | J34: 1.52 | K34: 0.43 | L34: 0.68 | M34: 0 | N34: 14 | O34: 112 | P34: 20.4 | Q34: 120 | R34: 501 | S34: 19 | T34: 47 | U34: 467 | V34: 585 | W34: 7.07
A35: Cereales | B35: Cereal desayuno, granola, con miel y pasas, Schullo | D35: Cereal, Breakfast, granola, with honey and raisins, Schullo | E35: 471.11 | F35: 15.56 | G35: 17.78 | H35: 62.22 | I35: 8.89 | J35: 2.22 | K35: 11.11 | L35: 3.33 | M35: 0 | R35: 66.67
A36: Cereales | B36: Cereal desayuno, granola, con trigo y miel | D36: Cereal, breakfast, granola, wheat & honey | E36: 441.38 | F36: 10.55 | G36: 11.62 | H36: 73.65 | I36: 10.2 | J36: 1.24 | K36: 6.6 | L36: 2.68 | M36: 2 | N36: 109 | O36: 357 | P36: 392 | Q36: 483 | R36: 50 | S36: 2.95 | T36: 0.2 | U36: 2 | V36: 37 | W36: 0.17
A37: Cereales | B37: Cereal desayuno, granola, muesli con frutas secas y nueces, promedio | D37: Cereal, breakfast, granola, muesli, dried fruit & nuts, average | E37: 393.4 | F37: 8 | G37: 4.6 | H37: 80 | I37: 5 | J37: 0.85 | K37: 2.12 | L37: 1.14 | M37: 0 | N37: 36 | O37: 273 | P37: 2 | Q37: 279 | R37: 376 | S37: 1.1 | T37: 0 | U37: 0 | V37: 13 | W37: 0
A38: Cereales | B38: Cereal desayuno, granola, preparada en casa | D38: Cereal, breakfast, granola, homemade | E38: 488.99 | F38: 13.67 | G38: 24.31 | H38: 53.88 | I38: 8.9 | J38: 3.96 | K38: 10.95 | L38: 7.81 | M38: 0 | N38: 76 | O38: 431 | P38: 3.95 | Q38: 539 | R38: 26 | S38: 4.17 | T38: 1.2 | U38: 1 | V38: 84 | W38: 0
A39: Cereales | B39: Cereal desayuno, hojuelas azucaradas, zucaritas, Kellog’s | D39: Cereal, breakfast, sugared flakes, zucaritas, Kellogg’s | E39: 379.08 | F39: 3.3 | G39: 0.52 | H39: 90.3 | I39: 3.2 | J39: 0.17 | K39: 0.09 | L39: 0.3 | M39: 0 | N39: 5 | O39: 34 | P39: 14.5 | Q39: 73 | R39: 479 | S39: 0.18 | T39: 20 | U39: 517 | V39: 543 | W39: 5
A40: Cereales | B40: Cereal desayuno, hojuelas de maíz, original, Kellog’s | D40: Cereal, breakfast, corn flakes, natural, Kellogg’s | E40: 370 | F40: 7.5 | G40: 0.4 | H40: 84.1 | I40: 3.3 | J40: 0.12 | K40: 0.07 | L40: 0.2 | M40: 0 | N40: 5 | O40: 102 | P40: 28.9 | Q40: 168 | R40: 729 | S40: 1 | T40: 21 | U40: 490 | V40: 34 | W40: 357
A41: Cereales | B41: Cereal desayuno, hojuelas de trigo, All-bran | D41: Cereal, breakfast, wheat flakes, All-bran | E41: 393.62 | F41: 13.14 | G41: 4.9 | H41: 74.24 | I41: 29.3 | J41: 0.64 | K41: 0.67 | L41: 2.11 | M41: 0 | N41: 389 | O41: 1150 | P41: 17.6 | Q41: 1020 | R41: 242 | S41: 12.4 | T41: 20 | U41: 525 | V41: 2198 | W41: 18.8
...

Sheet DIETA
A1: Grupo | B1: Alimento | C1: Nombre en Inglés | D1: Gramos | E1: Energía calculada (Kcal) | F1: Proteína (g) | G1: Grasa total (g) | H1: Carbohidratos (g) | I1: Fibra (g) | J1: AGS (g) | K1: AGM (g) | L1: AGPI (g) | M1: Colesterol (mg) | N1: Calcio (mg) | O1: Fósforo (mg) | P1: Ratio (Fos/Prot) | Q1: Hierro (mg) | R1: Potasio (mg) | S1: Sodio (mg) | T1: Zinc (mg) | U1: Vitamina C (mg) | V1: Vitamina A (µg ERE) | W1: Folatos (µg) | X1: Vitamina B12 (µg)
A3: Cereales | B3: Amaranto, grano seco | C3: Amaranth, grain, dry, uncooked | D3: 100 | E3: =$D3*TCA!E3/100 -> 381.07 | F3: =$D3*TCA!F3/100 -> 14.45 | G3: =$D3*TCA!G3/100 -> 6.51 | H3: =$D3*TCA!H3/100 -> 66.17 | I3: =$D3*TCA!I3/100 -> 9.3 | J3: =$D3*TCA!J3/100 -> 1.66 | K3: =$D3*TCA!K3/100 -> 1.43 | L3: =$D3*TCA!L3/100 -> 2.89 | ... O3: =$D3*TCA!O3/100 -> 455 | P3: =O3/F3 -> 31.487889 | Q3: =$D3*TCA!P3/100 -> 7.59 | R3: =$D3*TCA!Q3/100 -> 366 | S3: =$D3*TCA!R3/100 -> 21 | T3: =$D3*TCA!S3/100 -> 3.18 | U3: =$D3*TCA!T3/100 -> 4 | V3: =$D3*TCA!U3/100 -> 0 | W3: =$D3*TCA!V3/100 -> 49 | X3: =$D3*TCA!W3/100 -> 0
A4: Cereales | B4: Arroz blanco grano largo, cocido | C4: Rice, white, long-grain, unenriched, cooked, with salt | D4: 100 | E4: =$D4*TCA!E4/100 -> 125.96 | F4: =$D4*TCA!F4/100 -> 2.69 | G4: =$D4*TCA!G4/100 -> 0.28 | H4: =$D4*TCA!H4/100 -> 28.17 | I4: =$D4*TCA!I4/100 -> 0.4 | J4: =$D4*TCA!J4/100 -> 0.08 | K4: =$D4*TCA!K4/100 -> 0.09 | L4: =$D4*TCA!L4/100 -> 0.08 | ... O4: =$D4*TCA!O4/100 -> 43 | P4: =O4/F4 -> 15.98513 | Q4: =$D4*TCA!P4/100 -> 0.2 | R4: =$D4*TCA!Q4/100 -> 35 | S4: =$D4*TCA!R4/100 -> 382 | T4: =$D4*TCA!S4/100 -> 0.49 | U4: =$D4*TCA!T4/100 -> 0 | V4: =$D4*TCA!U4/100 -> 0 | W4: =$D4*TCA!V4/100 -> 3 | X4: =$D4*TCA!W4/100 -> 0
A5: Cereales | B5: Arroz blanco, grano corto | C5: Rice, white, short-grain, unenriched, raw | D5: 100 | E5: =$D5*TCA!E5/100 -> 347.28 | F5: =$D5*TCA!F5/100 -> 6.5 | G5: =$D5*TCA!G5/100 -> 0.52 | H5: =$D5*TCA!H5/100 -> 79.15 | I5: =$D5*TCA!I5/100 -> 0 | J5: =$D5*TCA!J5/100 -> 0.14 | K5: =$D5*TCA!K5/100 -> 0.16 | L5: =$D5*TCA!L5/100 -> 0.14 | ... O5: =$D5*TCA!O5/100 -> 95 | P5: =O5/F5 -> 14.615385 | Q5: =$D5*TCA!P5/100 -> 0.8 | R5: =$D5*TCA!Q5/100 -> 76 | S5: =$D5*TCA!R5/100 -> 1 | T5: =$D5*TCA!S5/100 -> 1.1 | U5: =$D5*TCA!T5/100 -> 0 | V5: =$D5*TCA!U5/100 -> 0 | W5: =$D5*TCA!V5/100 -> 6 | X5: =$D5*TCA!W5/100 -> 0
A6: Cereales | B6: Arroz blanco, grano corto, cocido | C6: Rice, white, short-grain, unenriched, cooked | D6: 100 | E6: =$D6*TCA!E6/100 -> 126.07 | F6: =$D6*TCA!F6/100 -> 2.36 | G6: =$D6*TCA!G6/100 -> 0.19 | H6: =$D6*TCA!H6/100 -> 28.73 | I6: =$D6*TCA!I6/100 -> 0 | J6: =$D6*TCA!J6/100 -> 0.05 | K6: =$D6*TCA!K6/100 -> 0.06 | L6: =$D6*TCA!L6/100 -> 0.05 | ... O6: =$D6*TCA!O6/100 -> 33 | P6: =O6/F6 -> 13.983051 | Q6: =$D6*TCA!P6/100 -> 0.2 | R6: =$D6*TCA!Q6/100 -> 26 | S6: =$D6*TCA!R6/100 -> 0 | T6: =$D6*TCA!S6/100 -> 0.4 | U6: =$D6*TCA!T6/100 -> 0 | V6: =$D6*TCA!U6/100 -> 0 | W6: =$D6*TCA!V6/100 -> 2 | X6: =$D6*TCA!W6/100 -> 0
A7: Cereales | B7: Arroz blanco, grano largo crudo | C7: Rice, white, long-grain, raw, unenriched | D7: 100 | E7: =$D7*TCA!E7/100 -> 354.26 | F7: =$D7*TCA!F7/100 -> 7.13 | G7: =$D7*TCA!G7/100 -> 0.66 | H7: =$D7*TCA!H7/100 -> 79.95 | I7: =$D7*TCA!I7/100 -> 1.3 | J7: =$D7*TCA!J7/100 -> 0.18 | K7: =$D7*TCA!K7/100 -> 0.21 | L7: =$D7*TCA!L7/100 -> 0.18 | ... O7: =$D7*TCA!O7/100 -> 115 | P7: =O7/F7 -> 16.129032 | Q7: =$D7*TCA!P7/100 -> 0.8 | R7: =$D7*TCA!Q7/100 -> 115 | S7: =$D7*TCA!R7/100 -> 5 | T7: =$D7*TCA!S7/100 -> 1.09 | U7: =$D7*TCA!T7/100 -> 0 | V7: =$D7*TCA!U7/100 -> 0 | W7: =$D7*TCA!V7/100 -> 8 | X7: =$D7*TCA!W7/100 -> 0
A8: Cereales | B8: Arroz blanco, grano largo, parbolizado, cocido | C8: Rice, white, long-grain, parabolized, unenriched, cooked | D8: 100 | E8: =$D8*TCA!E8/100 -> 119.17 | F8: =$D8*TCA!F8/100 -> 2.91 | G8: =$D8*TCA!G8/100 -> 0.37 | H8: =$D8*TCA!H8/100 -> 26.05 | I8: =$D8*TCA!I8/100 -> 0.9 | J8: =$D8*TCA!J8/100 -> 0.07 | K8: =$D8*TCA!K8/100 -> 0.07 | L8: =$D8*TCA!L8/100 -> 0.09 | ... O8: =$D8*TCA!O8/100 -> 55 | P8: =O8/F8 -> 18.900344 | Q8: =$D8*TCA!P8/100 -> 0.24 | R8: =$D8*TCA!Q8/100 -> 56 | S8: =$D8*TCA!R8/100 -> 2 | T8: =$D8*TCA!S8/100 -> 0.37 | U8: =$D8*TCA!T8/100 -> 0 | V8: =$D8*TCA!U8/100 -> 0 | W8: =$D8*TCA!V8/100 -> 3 | X8: =$D8*TCA!W8/100 -> 0
A9: Cereales | B9: Arroz blanco, grano largo, parbolizado, crudo | C9: Rice, white, long-grain, parabolized, unenriched, dry | D9: 100 | E9: =$D9*TCA!E9/100 -> 362.87 | F9: =$D9*TCA!F9/100 -> 7.51 | G9: =$D9*TCA!G9/100 -> 1.03 | H9: =$D9*TCA!H9/100 -> 80.89 | I9: =$D9*TCA!I9/100 -> 1.8 | J9: =$D9*TCA!J9/100 -> 0.29 | K9: =$D9*TCA!K9/100 -> 0.26 | L9: =$D9*TCA!L9/100 -> 0.32 | ... O9: =$D9*TCA!O9/100 -> 153 | P9: =O9/F9 -> 20.372836 | Q9: =$D9*TCA!P9/100 -> 0.74 | R9: =$D9*TCA!Q9/100 -> 174 | S9: =$D9*TCA!R9/100 -> 2 | T9: =$D9*TCA!S9/100 -> 1.02 | U9: =$D9*TCA!T9/100 -> 0 | V9: =$D9*TCA!U9/100 -> 0 | W9: =$D9*TCA!V9/100 -> 8 | X9: =$D9*TCA!W9/100 -> 0
A10: Cereales | B10: Arroz blanco, grano medio, cocido | C10: Rice, white, medium-grain, unenriched, cooked | D10: 100 | E10: =$D10*TCA!E10/100 -> 125.77 | F10: =$D10*TCA!F10/100 -> 2.38 | G10: =$D10*TCA!G10/100 -> 0.21 | H10: =$D10*TCA!H10/100 -> 28.59 | I10: =$D10*TCA!I10/100 -> 0 | J10: =$D10*TCA!J10/100 -> 0.06 | K10: =$D10*TCA!K10/100 -> 0.07 | L10: =$D10*TCA!L10/100 -> 0.06 | ... O10: =$D10*TCA!O10/100 -> 37 | P10: =O10/F10 -> 15.546218 | Q10: =$D10*TCA!P10/100 -> 0.2 | R10: =$D10*TCA!Q10/100 -> 29 | S10: =$D10*TCA!R10/100 -> 0 | T10: =$D10*TCA!S10/100 -> 0.42 | U10: =$D10*TCA!T10/100 -> 0 | V10: =$D10*TCA!U10/100 -> 0 | W10: =$D10*TCA!V10/100 -> 2 | X10: =$D10*TCA!W10/100 -> 0
A11: Cereales | B11: Arroz blanco, grano medio, crudo | C11: Rice, white, medium-grain, unenriched, raw | D11: 100 | E11: =$D11*TCA!E11/100 -> 349.02 | F11: =$D11*TCA!F11/100 -> 6.61 | G11: =$D11*TCA!G11/100 -> 0.58 | H11: =$D11*TCA!H11/100 -> 79.34 | I11: =$D11*TCA!I11/100 -> 0 | J11: =$D11*TCA!J11/100 -> 0.16 | K11: =$D11*TCA!K11/100 -> 0.18 | L11: =$D11*TCA!L11/100 -> 0.16 | ... O11: =$D11*TCA!O11/100 -> 108 | P11: =O11/F11 -> 16.33888 | Q11: =$D11*TCA!P11/100 -> 0.8 | R11: =$D11*TCA!Q11/100 -> 86 | S11: =$D11*TCA!R11/100 -> 1 | T11: =$D11*TCA!S11/100 -> 1.16 | U11: =$D11*TCA!T11/100 -> 0 | V11: =$D11*TCA!U11/100 -> 0 | W11: =$D11*TCA!V11/100 -> 9 | X11: =$D11*TCA!W11/100 -> 0
A12: Cereales | B12: Arroz blanco, pulido, enriquecido,precocido | C12: Rice, white, long-grain, precooked, enriched, dry | D12: 100 | E12: =$D12*TCA!E12/100 -> 369.02 | F12: =$D12*TCA!F12/100 -> 7.82 | G12: =$D12*TCA!G12/100 -> 0.94 | H12: =$D12*TCA!H12/100 -> 82.32 | I12: =$D12*TCA!I12/100 -> 1.9 | J12: =$D12*TCA!J12/100 -> 0.15 | K12: =$D12*TCA!K12/100 -> 0.14 | L12: =$D12*TCA!L12/100 -> 0.22 | ... O12: =$D12*TCA!O12/100 -> 118 | P12: =O12/F12 -> 15.089514 | Q12: =$D12*TCA!P12/100 -> 6.3 | R12: =$D12*TCA!Q12/100 -> 27 | S12: =$D12*TCA!R12/100 -> 10 | T12: =$D12*TCA!S12/100 -> 1.43 | U12: =$D12*TCA!T12/100 -> 0 | V12: =$D12*TCA!U12/100 -> 0 | W12: =$D12*TCA!V12/100 -> 466 | X12: =$D12*TCA!W12/100 -> 0
A13: Cereales | B13: Arroz integral, grano largo cocido | C13: Rice, brown, long-grain, cooked | D13: 100 | E13: =$D13*TCA!E13/100 -> 122.01 | F13: =$D13*TCA!F13/100 -> 2.74 | G13: =$D13*TCA!G13/100 -> 0.97 | H13: =$D13*TCA!H13/100 -> 25.58 | I13: =$D13*TCA!I13/100 -> 1.6 | J13: =$D13*TCA!J13/100 -> 0.26 | K13: =$D13*TCA!K13/100 -> 0.37 | L13: =$D13*TCA!L13/100 -> 0.37 | ... O13: =$D13*TCA!O13/100 -> 103 | P13: =O13/F13 -> 37.591241 | Q13: =$D13*TCA!P13/100 -> 0.56 | R13: =$D13*TCA!Q13/100 -> 86 | S13: =$D13*TCA!R13/100 -> 4 | T13: =$D13*TCA!S13/100 -> 0.71 | U13: =$D13*TCA!T13/100 -> 0 | V13: =$D13*TCA!U13/100 -> 0 | W13: =$D13*TCA!V13/100 -> 9 | X13: =$D13*TCA!W13/100 -> 0
A14: Cereales | B14: Arroz integral, grano largo crudo | C14: Rice, brown, long-grain, raw | D14: 100 | E14: =$D14*TCA!E14/100 -> 363.96 | F14: =$D14*TCA!F14/100 -> 7.54 | G14: =$D14*TCA!G14/100 -> 3.2 | H14: =$D14*TCA!H14/100 -> 76.25 | I14: =$D14*TCA!I14/100 -> 3.6 | J14: =$D14*TCA!J14/100 -> 0.59 | K14: =$D14*TCA!K14/100 -> 1.05 | L14: =$D14*TCA!L14/100 -> 1 | ... O14: =$D14*TCA!O14/100 -> 311 | P14: =O14/F14 -> 41.246684 | Q14: =$D14*TCA!P14/100 -> 1.29 | R14: =$D14*TCA!Q14/100 -> 250 | S14: =$D14*TCA!R14/100 -> 5 | T14: =$D14*TCA!S14/100 -> 2.13 | U14: =$D14*TCA!T14/100 -> 0 | V14: =$D14*TCA!U14/100 -> 0 | W14: =$D14*TCA!V14/100 -> 23 | X14: =$D14*TCA!W14/100 -> 0
... A149: Cereales | B149: Trigo, sémola, harina gruesa, no enriquecida | C149: Semolina, wheat flour, unenriched | D149: 100 | E149: =$D149*TCA!E149/100 -> 351.49 | F149: =$D149*TCA!F149/100 -> 12.68 | G149: =$D149*TCA!G149/100 -> 1.05 | H149: =$D149*TCA!H149/100 -> 72.83 | I149: =$D149*TCA!I149/100 -> 3.9 | J149: =$D149*TCA!J149/100 -> 0.15 | K149: =$D149*TCA!K149/100 -> 0.12 | L149: =$D149*TCA!L149/100 -> 0.43 | ... O149: =$D149*TCA!O149/100 -> 136 | P149: =O149/F149 -> 10.725552 | Q149: =$D149*TCA!P149/100 -> 1.23 | R149: =$D149*TCA!Q149/100 -> 186 | S149: =$D149*TCA!R149/100 -> 1 | T149: =$D149*TCA!S149/100 -> 1.05 | U149: =$D149*TCA!T149/100 -> 0 | V149: =$D149*TCA!U149/100 -> 0 | W149: =$D149*TCA!V149/100 -> 72 | X149: =$D149*TCA!W149/100 -> 0
D150: 100
A151: Plátanos y tubérculos | B151: Achira, blanca, rizoma, raíz | C151: Achira, white, root | D151: 100 | E151: =$D151*TCA!E151/100 -> 101.7 | F151: =$D151*TCA!F151/100 -> 1.4 | G151: =$D151*TCA!G151/100 -> 0.1 | H151: =$D151*TCA!H151/100 -> 23.8 | I151: =$D151*TCA!I151/100 -> 0 | J151: =$D151*TCA!J151/100 -> 0 | K151: =$D151*TCA!K151/100 -> 0 | L151: =$D151*TCA!L151/100 -> 0 | ... O151: =$D151*TCA!O151/100 -> 58 | P151: =O151/F151 -> 41.428571 | Q151: =$D151*TCA!P151/100 -> 0.7 | R151: =$D151*TCA!Q151/100 -> 0 | S151: =$D151*TCA!R151/100 -> 0 | T151: =$D151*TCA!S151/100 -> 0 | U151: =$D151*TCA!T151/100 -> 0.7 | V151: =$D151*TCA!U151/100 -> 0 | W151: =$D151*TCA!V151/100 -> 0 | X151: =$D151*TCA!W151/100 -> 0
A152: Plátanos y tubérculos | B152: Achira, morada, rizoma, raíz | C152: Achira, purple, root | D152: 100 | E152: =$D152*TCA!E152/100 -> 99.3 | F152: =$D152*TCA!F152/100 -> 1.4 | G152: =$D152*TCA!G152/100 -> 0.1 | H152: =$D152*TCA!H152/100 -> 23.2 | I152: =$D152*TCA!I152/100 -> 0 | J152: =$D152*TCA!J152/100 -> 0 | K152: =$D152*TCA!K152/100 -> 0 | L152: =$D152*TCA!L152/100 -> 0 | ... O152: =$D152*TCA!O152/100 -> 91 | P152: =O152/F152 -> 65 | Q152: =$D152*TCA!P152/100 -> 1.4 | R152: =$D152*TCA!Q152/100 -> 0 | S152: =$D152*TCA!R152/100 -> 0 | T152: =$D152*TCA!S152/100 -> 0 | U152: =$D152*TCA!T152/100 -> 0.1 | V152: =$D152*TCA!U152/100 -> 0 | W152: =$D152*TCA!V152/100 -> 0 | X152: =$D152*TCA!W152/100 -> 0
A153: Plátanos y tubérculos | B153: Almidón, de achira, harina de flecha | C153: Starch Achira, Arrowroot flour | D153: 100 | E153: =$D153*TCA!E153/100 -> 354.7 | F153: =$D153*TCA!F153/100 -> 0.3 | G153: =$D153*TCA!G153/100 -> 0.1 | H153: =$D153*TCA!H153/100 -> 88.15 | I153: =$D153*TCA!I153/100 -> 3.4 | J153: =$D153*TCA!J153/100 -> 0.02 | K153: =$D153*TCA!K153/100 -> 0 | L153: =$D153*TCA!L153/100 -> 0.05 | ... O153: =$D153*TCA!O153/100 -> 5 | P153: =O153/F153 -> 16.666667 | Q153: =$D153*TCA!P153/100 -> 0.33 | R153: =$D153*TCA!Q153/100 -> 11 | S153: =$D153*TCA!R153/100 -> 2 | T153: =$D153*TCA!S153/100 -> 0.07 | U153: =$D153*TCA!T153/100 -> 0 | V153: =$D153*TCA!U153/100 -> 0 | W153: =$D153*TCA!V153/100 -> 7 | X153: =$D153*TCA!W153/100 -> 0
A154: Plátanos y tubérculos | B154: Almidón, de yuca o mandioca | C154: Cassava, flour | D154: 100 | E154: =$D154*TCA!E154/100 -> 335.3 | F154: =$D154*TCA!F154/100 -> 1.7 | G154: =$D154*TCA!G154/100 -> 0.5 | H154: =$D154*TCA!H154/100 -> 81 | I154: =$D154*TCA!I154/100 -> 0 | J154: =$D154*TCA!J154/100 -> 0 | K154: =$D154*TCA!K154/100 -> 0 | L154: =$D154*TCA!L154/100 -> 0 | ... O154: =$D154*TCA!O154/100 -> 104 | P154: =O154/F154 -> 61.176471 | Q154: =$D154*TCA!P154/100 -> 5.4 | R154: =$D154*TCA!Q154/100 -> 0 | S154: =$D154*TCA!R154/100 -> 0 | T154: =$D154*TCA!S154/100 -> 0 | U154: =$D154*TCA!T154/100 -> 14 | V154: =$D154*TCA!U154/100 -> 0 | W154: =$D154*TCA!V154/100 -> 0 | X154: =$D154*TCA!W154/100 -> 0
A155: Plátanos y tubérculos | B155: Camote, con cáscara, cocido | C155: Sweet potato, unpeeled, cooked | D155: 100 | E155: =$D155*TCA!E155/100 -> 77.62 | F155: =$D155*TCA!F155/100 -> 1.37 | G155: =$D155*TCA!G155/100 -> 0.14 | H155: =$D155*TCA!H155/100 -> 17.72 | I155: =$D155*TCA!I155/100 -> 2.5 | J155: =$D155*TCA!J155/100 -> 0.04 | K155: =$D155*TCA!K155/100 -> 0 | L155: =$D155*TCA!L155/100 -> 0.08 | ... O155: =$D155*TCA!O155/100 -> 32 | P155: =O155/F155 -> 23.357664 | Q155: =$D155*TCA!P155/100 -> 0.72 | R155: =$D155*TCA!Q155/100 -> 230 | S155: =$D155*TCA!R155/100 -> 27 | T155: =$D155*TCA!S155/100 -> 0.2 | U155: =$D155*TCA!T155/100 -> 13 | V155: =$D155*TCA!U155/100 -> 787 | W155: =$D155*TCA!V155/100 -> 6 | X155: =$D155*TCA!W155/100 -> 0
A156: Plátanos y tubérculos | B156: Camote, con cáscara, crudo | C156: Sweet potatoe, unpeeled, raw | D156: 100 | E156: =$D156*TCA!E156/100 -> 87.21 | F156: =$D156*TCA!F156/100 -> 1.57 | G156: =$D156*TCA!G156/100 -> 0.05 | H156: =$D156*TCA!H156/100 -> 20.12 | I156: =$D156*TCA!I156/100 -> 3 | J156: =$D156*TCA!J156/100 -> 0.02 | K156: =$D156*TCA!K156/100 -> 0 | L156: =$D156*TCA!L156/100 -> 0.01 | ... O156: =$D156*TCA!O156/100 -> 47 | P156: =O156/F156 -> 29.936306 | Q156: =$D156*TCA!P156/100 -> 0.61 | R156: =$D156*TCA!Q156/100 -> 337 | S156: =$D156*TCA!R156/100 -> 55 | T156: =$D156*TCA!S156/100 -> 0.3 | U156: =$D156*TCA!T156/100 -> 2 | V156: =$D156*TCA!U156/100 -> 709 | W156: =$D156*TCA!V156/100 -> 11 | X156: =$D156*TCA!W156/100 -> 0
A157: Plátanos y tubérculos | B157: Harina de camote, Vitavilena | C157: Sweet potato flour, Vitavilena | D157: 100 | E157: =$D157*TCA!E157/100 -> 333.33 | F157: =$D157*TCA!F157/100 -> 3.33 | G157: =$D157*TCA!G157/100 -> 0 | H157: =$D157*TCA!H157/100 -> 80 | I157: =$D157*TCA!I157/100 -> 0 | J157: =$D157*TCA!J157/100 -> 0 | K157: =$D157*TCA!K157/100 -> 0 | L157: =$D157*TCA!L157/100 -> 0 | ... O157: =$D157*TCA!O157/100 -> 0 | P157: =O157/F157 -> 0 | Q157: =$D157*TCA!P157/100 -> 0 | R157: =$D157*TCA!Q157/100 -> 0 | S157: =$D157*TCA!R157/100 -> 166.67 | T157: =$D157*TCA!S157/100 -> 0 | U157: =$D157*TCA!T157/100 -> 0 | V157: =$D157*TCA!U157/100 -> 0 | W157: =$D157*TCA!V157/100 -> 0 | X157: =$D157*TCA!W157/100 -> 0
A158: Plátanos y tubérculos | B158: Harina de plátano | C158: Banana flour | D158: 100 | E158: =$D158*TCA!E158/100 -> 334.4 | F158: =$D158*TCA!F158/100 -> 3.1 | G158: =$D158*TCA!G158/100 -> 0.4 | H158: =$D158*TCA!H158/100 -> 79.6 | I158: =$D158*TCA!I158/100 -> 9.9 | J158: =$D158*TCA!J158/100 -> 0.03 | K158: =$D158*TCA!K158/100 -> 0.02 | L158: =$D158*TCA!L158/100 -> 0.05 | ... O158: =$D158*TCA!O158/100 -> 104 | P158: =O158/F158 -> 33.548387 | Q158: =$D158*TCA!P158/100 -> 3.9 | R158: =$D158*TCA!Q158/100 -> 0 | S158: =$D158*TCA!R158/100 -> 0 | T158: =$D158*TCA!S158/100 -> 0.61 | U158: =$D158*TCA!T158/100 -> 1.3 | V158: =$D158*TCA!U158/100 -> 0 | W158: =$D158*TCA!V158/100 -> 0 | X158: =$D158*TCA!W158/100 -> 0
A159: Plátanos y tubérculos | B159: Mashua | C159: Mashua | D159: 100 | E159: =$D159*TCA!E159/100 -> 46.1 | F159: =$D159*TCA!F159/100 -> 0.7 | G159: =$D159*TCA!G159/100 -> 0.1 | H159: =$D159*TCA!H159/100 -> 10.6 | I159: =$D159*TCA!I159/100 -> 2.9 | J159: =$D159*TCA!J159/100 -> 0 | K159: =$D159*TCA!K159/100 -> 0 | L159: =$D159*TCA!L159/100 -> 0 | ... O159: =$D159*TCA!O159/100 -> 0 | P159: =O159/F159 -> 0 | Q159: =$D159*TCA!P159/100 -> 0.37 | R159: =$D159*TCA!Q159/100 -> 0 | S159: =$D159*TCA!R159/100 -> 0 | T159: =$D159*TCA!S159/100 -> 0.28 | U159: =$D159*TCA!T159/100 -> 42.06 | V159: =$D159*TCA!U159/100 -> 12 | W159: =$D159*TCA!V159/100 -> 0 | X159: =$D159*TCA!W159/100 -> 0
A160: Plátanos y tubérculos | B160: Ñame, yam, crudo | C160: Yam, raw | D160: 100 | E160: =$D160*TCA!E160/100 -> 119.17 | F160: =$D160*TCA!F160/100 -> 1.53 | G160: =$D160*TCA!G160/100 -> 0.17 | H160: =$D160*TCA!H160/100 -> 27.88 | I160: =$D160*TCA!I160/100 -> 4.1 | J160: =$D160*TCA!J160/100 -> 0.04 | K160: =$D160*TCA!K160/100 -> 0.01 | L160: =$D160*TCA!L160/100 -> 0.08 | ... O160: =$D160*TCA!O160/100 -> 55 | P160: =O160/F160 -> 35.947712 | Q160: =$D160*TCA!P160/100 -> 0.54 | R160: =$D160*TCA!Q160/100 -> 816 | S160: =$D160*TCA!R160/100 -> 9 | T160: =$D160*TCA!S160/100 -> 0.24 | U160: =$D160*TCA!T160/100 -> 17 | V160: =$D160*TCA!U160/100 -> 7 | W160: =$D160*TCA!V160/100 -> 23 | X160: =$D160*TCA!W160/100 -> 0
A161: Plátanos y tubérculos | B161: Ñame, yam, escurrido, cocido sin sal | C161: Yam, cooked, drained, without salt | D161: 100 | E161: =$D161*TCA!E161/100 -> 117.54 | F161: =$D161*TCA!F161/100 -> 1.49 | G161: =$D161*TCA!G161/100 -> 0.14 | H161: =$D161*TCA!H161/100 -> 27.58 | I161: =$D161*TCA!I161/100 -> 3.9 | J161: =$D161*TCA!J161/100 -> 0.03 | K161: =$D161*TCA!K161/100 -> 0 | L161: =$D161*TCA!L161/100 -> 0.06 | ... O161: =$D161*TCA!O161/100 -> 49 | P161: =O161/F161 -> 32.885906 | Q161: =$D161*TCA!P161/100 -> 0.52 | R161: =$D161*TCA!Q161/100 -> 670 | S161: =$D161*TCA!R161/100 -> 8 | T161: =$D161*TCA!S161/100 -> 0.2 | U161: =$D161*TCA!T161/100 -> 12 | V161: =$D161*TCA!U161/100 -> 6 | W161: =$D161*TCA!V161/100 -> 16 | X161: =$D161*TCA!W161/100 -> 0
A162: Plátanos y tubérculos | B162: Oca, sin cáscara | C162: Oca, peeled | D162: 100 | E162: =$D162*TCA!E162/100 -> 65.2 | F162: =$D162*TCA!F162/100 -> 0.7 | G162: =$D162*TCA!G162/100 -> 0 | H162: =$D162*TCA!H162/100 -> 15.6 | I162: =$D162*TCA!I162/100 -> 2.4 | J162: =$D162*TCA!J162/100 -> 0 | K162: =$D162*TCA!K162/100 -> 0 | L162: =$D162*TCA!L162/100 -> 0 | ... O162: =$D162*TCA!O162/100 -> 0 | P162: =O162/F162 -> 0 | Q162: =$D162*TCA!P162/100 -> 0.47 | R162: =$D162*TCA!Q162/100 -> 0 | S162: =$D162*TCA!R162/100 -> 0 | T162: =$D162*TCA!S162/100 -> 0.14 | U162: =$D162*TCA!T162/100 -> 23.92 | V162: =$D162*TCA!U162/100 -> 0 | W162: =$D162*TCA!V162/100 -> 0 | X162: =$D162*TCA!W162/100 -> 0
... A181: Plátanos y tubérculos | B181: Zanahoria, blanca, cruda | C181: Parsnips, raw | D181: 100 | E181: =$D181*TCA!E181/100 -> 79.46 | F181: =$D181*TCA!F181/100 -> 1.2 | G181: =$D181*TCA!G181/100 -> 0.3 | H181: =$D181*TCA!H181/100 -> 17.99 | I181: =$D181*TCA!I181/100 -> 4.9 | J181: =$D181*TCA!J181/100 -> 0.05 | K181: =$D181*TCA!K181/100 -> 0.11 | L181: =$D181*TCA!L181/100 -> 0.05 | ... O181: =$D181*TCA!O181/100 -> 71 | P181: =O181/F181 -> 59.166667 | Q181: =$D181*TCA!P181/100 -> 0.59 | R181: =$D181*TCA!Q181/100 -> 375 | S181: =$D181*TCA!R181/100 -> 10 | T181: =$D181*TCA!S181/100 -> 0.59 | U181: =$D181*TCA!T181/100 -> 17 | V181: =$D181*TCA!U181/100 -> 0 | W181: =$D181*TCA!V181/100 -> 67 | X181: =$D181*TCA!W181/100 -> 0
D182: 100
A183: Frutas | B183: Aguacate, sin cáscara, promedio | C183: Avocado, peeled, ordinary, alla varieties | D183: 100 | E183: =$D183*TCA!E183/100 -> 174.06 | F183: =$D183*TCA!F183/100 -> 2 | G183: =$D183*TCA!G183/100 -> 14.66 | H183: =$D183*TCA!H183/100 -> 8.53 | I183: =$D183*TCA!I183/100 -> 6.7 | J183: =$D183*TCA!J183/100 -> 2.13 | K183: =$D183*TCA!K183/100 -> 9.8 | L183: =$D183*TCA!L183/100 -> 1.82 | ... O183: =$D183*TCA!O183/100 -> 52 | P183: =O183/F183 -> 26 | Q183: =$D183*TCA!P183/100 -> 0.55 | R183: =$D183*TCA!Q183/100 -> 485 | S183: =$D183*TCA!R183/100 -> 7 | T183: =$D183*TCA!S183/100 -> 0.64 | U183: =$D183*TCA!T183/100 -> 10 | V183: =$D183*TCA!U183/100 -> 7 | W183: =$D183*TCA!V183/100 -> 81 | X183: =$D183*TCA!W183/100 -> 0
A184: Frutas | B184: Aguacate, verde, sin cáscara, serrano | C184: Avocado, green, peeled, raw | D184: 100 | E184: =$D184*TCA!E184/100 -> 130.74 | F184: =$D184*TCA!F184/100 -> 2.23 | G184: =$D184*TCA!G184/100 -> 10.06 | H184: =$D184*TCA!H184/100 -> 7.82 | I184: =$D184*TCA!I184/100 -> 5.6 | J184: =$D184*TCA!J184/100 -> 1.96 | K184: =$D184*TCA!K184/100 -> 5.51 | L184: =$D184*TCA!L184/100 -> 1.68 | ... O184: =$D184*TCA!O184/100 -> 40 | P184: =O184/F184 -> 17.93722 | Q184: =$D184*TCA!P184/100 -> 0.17 | R184: =$D184*TCA!Q184/100 -> 351 | S184: =$D184*TCA!R184/100 -> 2 | T184: =$D184*TCA!S184/100 -> 0.4 | U184: =$D184*TCA!T184/100 -> 17.4 | V184: =$D184*TCA!U184/100 -> 7 | W184: =$D184*TCA!V184/100 -> 35 | X184: =$D184*TCA!W184/100 -> 0
A185: Frutas | B185: Arándano, deshidratado, Natures Heart | C185: Blueberries, dehydrated, Natures Heart | D185: 100 | E185: =$D185*TCA!E185/100 -> 320 | F185: =$D185*TCA!F185/100 -> 0 | G185: =$D185*TCA!G185/100 -> 0 | H185: =$D185*TCA!H185/100 -> 80 | I185: =$D185*TCA!I185/100 -> 1.67 | J185: =$D185*TCA!J185/100 -> 0 | K185: =$D185*TCA!K185/100 -> 0 | L185: =$D185*TCA!L185/100 -> 0 | ... O185: =$D185*TCA!O185/100 -> 0 | P185: =O185/F185 -> #DIV/0! | Q185: =$D185*TCA!P185/100 -> 0 | R185: =$D185*TCA!Q185/100 -> 0 | S185: =$D185*TCA!R185/100 -> 100 | T185: =$D185*TCA!S185/100 -> 0 | U185: =$D185*TCA!T185/100 -> 0 | V185: =$D185*TCA!U185/100 -> 0 | W185: =$D185*TCA!V185/100 -> 0 | X185: =$D185*TCA!W185/100 -> 0
A186: Frutas | B186: Arándano, deshidratado, promedio | C186: Blueberries, dehydrated, average | D186: 100 | E186: =$D186*TCA!E186/100 -> 340 | F186: =$D186*TCA!F186/100 -> 0 | G186: =$D186*TCA!G186/100 -> 0 | H186: =$D186*TCA!H186/100 -> 85 | I186: =$D186*TCA!I186/100 -> 5 | J186: =$D186*TCA!J186/100 -> 0 | K186: =$D186*TCA!K186/100 -> 0 | L186: =$D186*TCA!L186/100 -> 0 | ... O186: =$D186*TCA!O186/100 -> 0 | P186: =O186/F186 -> #DIV/0! | Q186: =$D186*TCA!P186/100 -> 0 | R186: =$D186*TCA!Q186/100 -> 0 | S186: =$D186*TCA!R186/100 -> 0 | T186: =$D186*TCA!S186/100 -> 0 | U186: =$D186*TCA!T186/100 -> 0 | V186: =$D186*TCA!U186/100 -> 0 | W186: =$D186*TCA!V186/100 -> 0 | X186: =$D186*TCA!W186/100 -> 0
A187: Frutas | B187: Arazá, fresco | C187: Araza, fresh | D187: 100 | E187: =$D187*TCA!E187/100 -> 36.7 | F187: =$D187*TCA!F187/100 -> 1.1 | G187: =$D187*TCA!G187/100 -> 1.1 | H187: =$D187*TCA!H187/100 -> 5.6 | I187: =$D187*TCA!I187/100 -> 0.9 | J187: =$D187*TCA!J187/100 -> 0 | K187: =$D187*TCA!K187/100 -> 0 | L187: =$D187*TCA!L187/100 -> 0 | ... O187: =$D187*TCA!O187/100 -> 0 | P187: =O187/F187 -> 0 | Q187: =$D187*TCA!P187/100 -> 0.8 | R187: =$D187*TCA!Q187/100 -> 222 | S187: =$D187*TCA!R187/100 -> 28 | T187: =$D187*TCA!S187/100 -> 0.4 | U187: =$D187*TCA!T187/100 -> 0 | V187: =$D187*TCA!U187/100 -> 0 | W187: =$D187*TCA!V187/100 -> 0 | X187: =$D187*TCA!W187/100 -> 0
A188: Frutas | B188: Babaco, maduro, pulpa | C188: Babaco, ripe, pulp | D188: 100 | E188: =$D188*TCA!E188/100 -> 31.4 | F188: =$D188*TCA!F188/100 -> 0.9 | G188: =$D188*TCA!G188/100 -> 0.2 | H188: =$D188*TCA!H188/100 -> 6.5 | I188: =$D188*TCA!I188/100 -> 0.5 | J188: =$D188*TCA!J188/100 -> 0 | K188: =$D188*TCA!K188/100 -> 0 | L188: =$D188*TCA!L188/100 -> 0 | ... O188: =$D188*TCA!O188/100 -> 14 | P188: =O188/F188 -> 15.555556 | Q188: =$D188*TCA!P188/100 -> 0.7 | R188: =$D188*TCA!Q188/100 -> 223 | S188: =$D188*TCA!R188/100 -> 10 | T188: =$D188*TCA!S188/100 -> 0.1 | U188: =$D188*TCA!T188/100 -> 0 | V188: =$D188*TCA!U188/100 -> 12 | W188: =$D188*TCA!V188/100 -> 0 | X188: =$D188*TCA!W188/100 -> 0
A189: Frutas | B189: Badea, tumbo costeño, fresca | C189: Badea, tumbo costeño, fresh | D189: 100 | E189: =$D189*TCA!E189/100 -> 21.8 | F189: =$D189*TCA!F189/100 -> 0.7 | G189: =$D189*TCA!G189/100 -> 0.2 | H189: =$D189*TCA!H189/100 -> 4.3 | I189: =$D189*TCA!I189/100 -> 0 | J189: =$D189*TCA!J189/100 -> 0 | K189: =$D189*TCA!K189/100 -> 0 | L189: =$D189*TCA!L189/100 -> 0 | ... O189: =$D189*TCA!O189/100 -> 17 | P189: =O189/F189 -> 24.285714 | Q189: =$D189*TCA!P189/100 -> 0.8 | R189: =$D189*TCA!Q189/100 -> 0 | S189: =$D189*TCA!R189/100 -> 0 | T189: =$D189*TCA!S189/100 -> 0 | U189: =$D189*TCA!T189/100 -> 15 | V189: =$D189*TCA!U189/100 -> 7 | W189: =$D189*TCA!V189/100 -> 0 | X189: =$D189*TCA!W189/100 -> 0
A190: Frutas | B190: Banano, guineo manzano, odatil, orito | C190: Banana, small, sweet, raw | D190: 100 | E190: =$D190*TCA!E190/100 -> 115.8 | F190: =$D190*TCA!F190/100 -> 1.1 | G190: =$D190*TCA!G190/100 -> 0.2 | H190: =$D190*TCA!H190/100 -> 27.4 | I190: =$D190*TCA!I190/100 -> 0 | J190: =$D190*TCA!J190/100 -> 0 | K190: =$D190*TCA!K190/100 -> 0 | L190: =$D190*TCA!L190/100 -> 0 | ... O190: =$D190*TCA!O190/100 -> 24 | P190: =O190/F190 -> 21.818182 | Q190: =$D190*TCA!P190/100 -> 0.6 | R190: =$D190*TCA!Q190/100 -> 370 | S190: =$D190*TCA!R190/100 -> 1 | T190: =$D190*TCA!S190/100 -> 0.17 | U190: =$D190*TCA!T190/100 -> 13 | V190: =$D190*TCA!U190/100 -> 14 | W190: =$D190*TCA!V190/100 -> 0 | X190: =$D190*TCA!W190/100 -> 0
A191: Frutas | B191: Banano, guineo, plátano seda | C191: Banana, raw | D191: 100 | E191: =$D191*TCA!E191/100 -> 98.69 | F191: =$D191*TCA!F191/100 -> 1.09 | G191: =$D191*TCA!G191/100 -> 0.33 | H191: =$D191*TCA!H191/100 -> 22.84 | I191: =$D191*TCA!I191/100 -> 2.6 | J191: =$D191*TCA!J191/100 -> 0.11 | K191: =$D191*TCA!K191/100 -> 0.03 | L191: =$D191*TCA!L191/100 -> 0.07 | ... O191: =$D191*TCA!O191/100 -> 22 | P191: =O191/F191 -> 20.183486 | Q191: =$D191*TCA!P191/100 -> 0.26 | R191: =$D191*TCA!Q191/100 -> 358 | S191: =$D191*TCA!R191/100 -> 1 | T191: =$D191*TCA!S191/100 -> 0.15 | U191: =$D191*TCA!T191/100 -> 9 | V191: =$D191*TCA!U191/100 -> 3 | W191: =$D191*TCA!V191/100 -> 20 | X191: =$D191*TCA!W191/100 -> 0
A192: Frutas | B192: Borojó, fresco | C192: Borojo fruit, raw | D192: 100 | E192: =$D192*TCA!E192/100 -> 133.4 | F192: =$D192*TCA!F192/100 -> 3 | G192: =$D192*TCA!G192/100 -> 0.6 | H192: =$D192*TCA!H192/100 -> 29 | I192: =$D192*TCA!I192/100 -> 0 | J192: =$D192*TCA!J192/100 -> 0 | K192: =$D192*TCA!K192/100 -> 0 | L192: =$D192*TCA!L192/100 -> 0 | ... O192: =$D192*TCA!O192/100 -> 0 | P192: =O192/F192 -> 0 | Q192: =$D192*TCA!P192/100 -> 6.9 | R192: =$D192*TCA!Q192/100 -> 464 | S192: =$D192*TCA!R192/100 -> 8 | T192: =$D192*TCA!S192/100 -> 1.5 | U192: =$D192*TCA!T192/100 -> 3 | V192: =$D192*TCA!U192/100 -> 0 | W192: =$D192*TCA!V192/100 -> 0 | X192: =$D192*TCA!W192/100 -> 0
A193: Frutas | B193: Capulí, capulin, capulina | C193: Capuli, capulin, capulina | D193: 100 | E193: =$D193*TCA!E193/100 -> 100.7 | F193: =$D193*TCA!F193/100 -> 2.1 | G193: =$D193*TCA!G193/100 -> 2.3 | H193: =$D193*TCA!H193/100 -> 17.9 | I193: =$D193*TCA!I193/100 -> 0 | J193: =$D193*TCA!J193/100 -> 0 | K193: =$D193*TCA!K193/100 -> 0 | L193: =$D193*TCA!L193/100 -> 0 | ... O193: =$D193*TCA!O193/100 -> 94 | P193: =O193/F193 -> 44.761905 | Q193: =$D193*TCA!P193/100 -> 1.2 | R193: =$D193*TCA!Q193/100 -> 0 | S193: =$D193*TCA!R193/100 -> 0 | T193: =$D193*TCA!S193/100 -> 0 | U193: =$D193*TCA!T193/100 -> 90 | V193: =$D193*TCA!U193/100 -> 0 | W193: =$D193*TCA!V193/100 -> 0 | X193: =$D193*TCA!W193/100 -> 0
...

Sheet MUJER
A1: MUJER
A2: Peso kg | B2: 82
A3: Talla | B3: 160 | L3: DESAYUNO | T3: DESAYUNO
A4: IMC | B4: =B2/((B3*0.01)^2) -> 32.03125 | E4: Nutrimento | F4: % | G4: Energía Kcal | H4: Gramos | O4: CHO (g) | P4: Prot (g) | Q4: Grasas (g) | W4: LUNES | Y4: MARTES | AA4: MIERCOLES | AC4: JUEVES | AE4: VIERNES
A5: Edad | B5: 42 | E5: CHO | F5: =100-F6-F7 -> 51.079347 | G5: =(C10*F5)/100 -> 700.4 | H5: =G5/4 -> 175.1 | L5: Grupo de alimento | M5: Subgrupo | N5: # de raciones de intercambio | O5: =G15 -> 50.028571 | P5: =H15 -> 23.428571 | Q5: =I15 -> 10.88254 | T5: Grupo de alimento | U5: Subgrupo | V5: # | W5: Descripción (alimento) | X5: Cantidad | Y5: Descripción (alimento) | Z5: Cantidad | AA5: Descripción (alimento) | AB5: Cantidad | AC5: Descripción (alimento) | AD5: Cantidad | AE5: Descripción (alimento) | AF5: Cantidad
A6: Kcal Extra | B6: 0 | E6: Proteínas | F6: =(G6*100)/C10 -> 23.920653 | G6: =H6*4 -> 328 | H6: =B2*B14 -> 82 | L6: Cereales, tuberculos y plátanos | M6: Altos en CHO y bajos en grasas | N6: 1 | O6: =VLOOKUP($M6,FORMULAS!$O$6:$P$8,2,FALSE)*N6 -> 30 | P6: =VLOOKUP($M6,FORMULAS!$O$6:$Q$8,3,FALSE)*N6 -> 4 | Q6: =VLOOKUP($M6,FORMULAS!$O$6:$R$8,4,FALSE)*N6 -> 1 | T6: Cereales, tuberculos y plátanos | U6: =M6 -> Altos en CHO y bajos en grasas | V6: =N6 -> 1
E7: Lípidos | F7: 25 | G7: =(C10*F7)/100 -> 342.8 | H7: =G7/9 -> 38.088889 | M7: Medios en CHO y bajos en grasas | N7: 0 | O7: =VLOOKUP($M7,FORMULAS!$O$6:$P$8,2,FALSE)*N7 -> 0 | P7: =VLOOKUP($M7,FORMULAS!$O$6:$Q$8,3,FALSE)*N7 -> 0 | Q7: =VLOOKUP($M7,FORMULAS!$O$6:$R$8,4,FALSE)*N7 -> 0 | U7: =M7 -> Medios en CHO y bajos en grasas | V7: =N7 -> 0
E8: Total | F8: =SUM(F5:F7) -> 100 | G8: =SUM(G5:G7) -> 1371.2 | H8: =SUM(H5:H7) -> 295.18889 | L8: Frutas | M8: Medias en CHO | N8: 0 | O8: =VLOOKUP($M8,FORMULAS!$O$9:$P$11,2,FALSE)*N8 -> 0 | P8: =VLOOKUP($M8,FORMULAS!$O$9:$Q$11,3,FALSE)*N8 -> 0 | Q8: =VLOOKUP($M8,FORMULAS!$O$9:$R$11,4,FALSE)*N8 -> 0 | T8: Frutas | U8: =M8 -> Medias en CHO | V8: =N8 -> 0
A9: GET | M9: Bajas en CHO | N9: 2 | O9: =VLOOKUP($M9,FORMULAS!$O$9:$P$11,2,FALSE)*N9 -> 20 | P9: =VLOOKUP($M9,FORMULAS!$O$9:$Q$11,3,FALSE)*N9 -> 2 | Q9: =VLOOKUP($M9,FORMULAS!$O$9:$R$11,4,FALSE)*N9 -> 0 | U9: =M9 -> Bajas en CHO | V9: =N9 -> 2
A10: Mujer | B10: mifflin | C10: 1371.2 | L10: Vegetales | M10: Bajos en CHO | N10: 0 | O10: =VLOOKUP($M10,FORMULAS!$O$12:$P$13,2,FALSE)*N10 -> 0 | P10: =VLOOKUP($M10,FORMULAS!$O$12:$Q$13,3,FALSE)*N10 -> 0 | Q10: =VLOOKUP($M10,FORMULAS!$O$12:$R$13,4,FALSE)*N10 -> 0 | T10: Vegetales | U10: =M10 -> Bajos en CHO | V10: =N10 -> 0
M11: Libre consumo | N11: 0 | O11: =VLOOKUP($M11,FORMULAS!$O$12:$P$13,2,FALSE)*N11 -> 0 | P11: =VLOOKUP($M11,FORMULAS!$O$12:$Q$13,3,FALSE)*N11 -> 0 | Q11: =VLOOKUP($M11,FORMULAS!$O$12:$R$13,4,FALSE)*N11 -> 0 | U11: =M11 -> Libre consumo | V11: =N11 -> 0
E12: Distribución de Alimentos | L12: Lácteos | M12: Enteros - altos en grasas | N12: 0 | O12: =VLOOKUP($M12,FORMULAS!$O$14:$P$18,2,FALSE)*N12 -> 0 | P12: =VLOOKUP($M12,FORMULAS!$O$14:$Q$18,3,FALSE)*N12 -> 0 | Q12: =VLOOKUP($M12,FORMULAS!$O$14:$R$18,4,FALSE)*N12 -> 0 | T12: Lácteos | U12: =M12 -> Enteros - altos en grasas | V12: =N12 -> 0
A13: Proteína g/kg/día | E13: # de fraccionamiento | I13: 7 | M13: Descremados y altos en CHO | N13: 1 | O13: =VLOOKUP($M13,FORMULAS!$O$14:$P$18,2,FALSE)*N13 -> 25 | P13: =VLOOKUP($M13,FORMULAS!$O$14:$Q$18,3,FALSE)*N13 -> 6 | Q13: =VLOOKUP($M13,FORMULAS!$O$14:$R$18,4,FALSE)*N13 -> 3 | U13: =M13 -> Descremados y altos en CHO | V13: =N13 -> 1
A14: Hipoproteico (g) | B14: =_xlfn.XLOOKUP(A14,FORMULAS!G23:G26,FORMULAS!H23:H26,"ROTO") -> 1 | E14: Tiempos de comida | F14: Fraccion | G14: CHO (g) | H14: Proteinas (g) | I14: Lipidos (g) | L14: Carnes, pescados y huevos | M14: Medios en grasas | N14: 1 | O14: =VLOOKUP($M14,FORMULAS!$O$19:$P$22,2,FALSE)*N14 -> 0 | P14: =VLOOKUP($M14,FORMULAS!$O$19:$Q$22,3,FALSE)*N14 -> 11 | Q14: =VLOOKUP($M14,FORMULAS!$O$19:$R$22,4,FALSE)*N14 -> 7 | T14: Carnes, pescados y huevos | U14: =M14 -> Medios en grasas | V14: =N14 -> 1
E15: Desayuno | F15: 2 | G15: =($H$5*$F15)/$I$13 -> 50.028571 | H15: =($H$6*$F15)/$I$13 -> 23.428571 | I15: =($H$7*$F15)/$I$13 -> 10.88254 | M15: Bajos en grasas | N15: 0 | O15: =VLOOKUP($M15,FORMULAS!$O$19:$P$22,2,FALSE)*N15 -> 0 | P15: =VLOOKUP($M15,FORMULAS!$O$19:$Q$22,3,FALSE)*N15 -> 0 | Q15: =VLOOKUP($M15,FORMULAS!$O$19:$R$22,4,FALSE)*N15 -> 0 | U15: =M15 -> Bajos en grasas | V15: =N15 -> 0
E16: Media mañana | F16: 1 | G16: =($H$5*$F16)/$I$13 -> 25.014286 | H16: =($H$6*$F16)/$I$13 -> 11.714286 | I16: =($H$7*$F16)/$I$13 -> 5.4412698 | M16: Embutidos | N16: 0 | O16: =VLOOKUP($M16,FORMULAS!$O$19:$P$22,2,FALSE)*N16 -> 0 | P16: =VLOOKUP($M16,FORMULAS!$O$19:$Q$22,3,FALSE)*N16 -> 0 | Q16: =VLOOKUP($M16,FORMULAS!$O$19:$R$22,4,FALSE)*N16 -> 0 | U16: =M16 -> Embutidos | V16: =N16 -> 0
A17: Deficit calorico | E17: Almuerzo | F17: 2 | G17: =($H$5*$F17)/$I$13 -> 50.028571 | H17: =($H$6*$F17)/$I$13 -> 23.428571 | I17: =($H$7*$F17)/$I$13 -> 10.88254 | L17: Leguminosas | M17: Leguminosas | N17: 0 | O17: =VLOOKUP($M17,FORMULAS!$O$23:$P$23,2,FALSE)*N17 -> 0 | P17: =VLOOKUP($M17,FORMULAS!$O$23:$Q$23,3,FALSE)*N17 -> 0 | Q17: =VLOOKUP($M17,FORMULAS!$O$23:$R$23,4,FALSE)*N17 -> 0 | T17: Leguminosas | U17: =M17 -> Leguminosas | V17: =N17 -> 0
A18: Obj en meses | B18: 4 | E18: Media tarde | F18: 1 | G18: =($H$5*$F18)/$I$13 -> 25.014286 | H18: =($H$6*$F18)/$I$13 -> 11.714286 | I18: =($H$7*$F18)/$I$13 -> 5.4412698 | L18: Grasas y frutos secos | M18: Altos en grasas y bajos en CHO | N18: 0 | O18: =VLOOKUP($M18,FORMULAS!$O$24:$P$27,2,FALSE)*N18 -> 0 | P18: =VLOOKUP($M18,FORMULAS!$O$24:$Q$27,3,FALSE)*N18 -> 0 | Q18: =VLOOKUP($M18,FORMULAS!$O$24:$R$27,4,FALSE)*N18 -> 0 | T18: Grasas y frutos secos | U18: =M18 -> Altos en grasas y bajos en CHO | V18: =N18 -> 0
A19: Semanas | B19: =B18*4 -> 16 | E19: Merienda | F19: 1 | G19: =($H$5*$F19)/$I$13 -> 25.014286 | H19: =($H$6*$F19)/$I$13 -> 11.714286 | I19: =($H$7*$F19)/$I$13 -> 5.4412698 | M19: Medios en grasas y bajor en CHO | N19: 1 | O19: =VLOOKUP($M19,FORMULAS!$O$24:$P$27,2,FALSE)*N19 -> 12 | P19: =VLOOKUP($M19,FORMULAS!$O$24:$Q$27,3,FALSE)*N19 -> 2 | Q19: =VLOOKUP($M19,FORMULAS!$O$24:$R$27,4,FALSE)*N19 -> 7 | U19: =M19 -> Medios en grasas y bajor en CHO | V19: =N19 -> 1
A20: % de pérdida | B20: 0.1 | E20: TOTAL | F20: =SUM(F15:F19) -> 7 | G20: =SUM(G15:G19) -> 175.1 | H20: =SUM(H15:H19) -> 82 | I20: =SUM(I15:I19) -> 38.088889 | L20: Azúcares y alimentos azucarados | M20: Azucares y alimentos azucarados | N20: 0 | O20: =VLOOKUP($M20,FORMULAS!$O$28:$P$28,2,FALSE)*N20 -> 0 | P20: =VLOOKUP($M20,FORMULAS!$O$28:$Q$28,3,FALSE)*N20 -> 0 | Q20: =VLOOKUP($M20,FORMULAS!$O$28:$R$28,4,FALSE)*N20 -> 0 | T20: Azúcares y alimentos azucarados | U20: =M20 -> Azucares y alimentos azucarados | V20: =N20 -> 0
A21: ¿? Kg pierde | B21: =B2*B20 -> 8.2 | N21: TOTAL | O21: =SUM(O6:O20) -> 87 | P21: =SUM(P6:P20) -> 25 | Q21: =SUM(Q6:Q20) -> 18 | U21: DETALLES
A22: Peso ideal | B22: =B2-B21 -> 73.8 | N22: BALANCE | O22: =O21-O5 -> 36.971429 | P22: =P21-P5 -> 1.5714286 | Q22: =Q21-Q5 -> 7.1174603
A23: Kcal para def | B23: =((B21*7000)/B19)/7 -> 512.5 | E23: Nutrimento | F23: 0.95 | G23: Real | H23: 1.05 | I23: % Adecuacion
A24: Kcal recomend | B24: =C10-B23 -> 858.7 | E24: CHO | F24: =G20*F23 -> 166.345 | G24: =SUMIF($N:$N,$N$21,$O:$O) -> 301 | H24: =G20*H23 -> 183.855 | I24: =G24/G20 -> 1.7190177
E25: Proteínas | F25: =H20*F23 -> 77.9 | G25: =SUMIF($N:$N,$N$21,$P:$P) -> 87.75 | H25: =H20*H23 -> 86.1 | I25: =G25/H20 -> 1.070122 | L25: MEDIA MAÑANA | T25: MEDIA MAÑANA
E26: Lípidos | F26: =I20*F23 -> 36.184444 | G26: =SUMIF($N:$N,$N$21,$Q:$Q) -> 70.25 | H26: =I20*H23 -> 39.993333 | I26: =G26/I20 -> 1.8443699 | O26: CHO (g) | P26: Prot (g) | Q26: Grasas (g) | W26: LUNES | Y26: MARTES | AA26: MIERCOLES | AC26: JUEVES | AE26: VIERNES
L27: Grupo de alimento | M27: Subgrupo | N27: # de raciones de intercambio | O27: =G16-O22 -> -11.957143 | P27: =H16-P22 -> 10.142857 | Q27: =I16-Q22 -> -1.6761905 | T27: Grupo de alimento | U27: Subgrupo | V27: # | W27: Descripción (alimento) | X27: Cantidad | Y27: Descripción (alimento) | Z27: Cantidad | AA27: Descripción (alimento) | AB27: Cantidad | AC27: Descripción (alimento) | AD27: Cantidad | AE27: Descripción (alimento) | AF27: Cantidad
L28: Cereales, tuberculos y plátanos | M28: Altos en CHO y bajos en grasas | N28: 0.5 | O28: =VLOOKUP($M28,FORMULAS!$O$6:$P$8,2,FALSE)*N28 -> 15 | P28: =VLOOKUP($M28,FORMULAS!$O$6:$Q$8,3,FALSE)*N28 -> 2 | Q28: =VLOOKUP($M28,FORMULAS!$O$6:$R$8,4,FALSE)*N28 -> 0.5 | T28: Cereales, tuberculos y plátanos | U28: =M28 -> Altos en CHO y bajos en grasas | V28: =N28 -> 0.5
M29: Medios en CHO y bajos en grasas | N29: 0 | O29: =VLOOKUP($M29,FORMULAS!$O$6:$P$8,2,FALSE)*N29 -> 0 | P29: =VLOOKUP($M29,FORMULAS!$O$6:$Q$8,3,FALSE)*N29 -> 0 | Q29: =VLOOKUP($M29,FORMULAS!$O$6:$R$8,4,FALSE)*N29 -> 0 | U29: =M29 -> Medios en CHO y bajos en grasas | V29: =N29 -> 0
E30: CHO | F30: 50% Cereales | G30: 10% Azucar | L30: Frutas | M30: Medias en CHO | N30: 0.5 | O30: =VLOOKUP($M30,FORMULAS!$O$9:$P$11,2,FALSE)*N30 -> 10 | P30: =VLOOKUP($M30,FORMULAS!$O$9:$Q$11,3,FALSE)*N30 -> 0.5 | Q30: =VLOOKUP($M30,FORMULAS!$O$9:$R$11,4,FALSE)*N30 -> 0 | T30: Frutas | U30: =M30 -> Medias en CHO | V30: =N30 -> 0.5
E31: Teorico | F31: =H5/2 -> 87.55 | G31: =H5*10/100 -> 17.51 | M31: Bajas en CHO | N31: 0 | O31: =VLOOKUP($M31,FORMULAS!$O$9:$P$11,2,FALSE)*N31 -> 0 | P31: =VLOOKUP($M31,FORMULAS!$O$9:$Q$11,3,FALSE)*N31 -> 0 | Q31: =VLOOKUP($M31,FORMULAS!$O$9:$R$11,4,FALSE)*N31 -> 0 | U31: =M31 -> Bajas en CHO | V31: =N31 -> 0
E32: Real | F32: =SUMIF($L:$L,$L$6,$O:$O) -> 105 | G32: =SUMIF($M:$M,$M$108,$O:$O) -> 30 | L32: Vegetales | M32: Bajos en CHO | N32: 0 | O32: =VLOOKUP($M32,FORMULAS!$O$12:$P$13,2,FALSE)*N32 -> 0 | P32: =VLOOKUP($M32,FORMULAS!$O$12:$Q$13,3,FALSE)*N32 -> 0 | Q32: =VLOOKUP($M32,FORMULAS!$O$12:$R$13,4,FALSE)*N32 -> 0 | T32: Vegetales | U32: =M32 -> Bajos en CHO | V32: =N32 -> 0
M33: Libre consumo | N33: 0 | O33: =VLOOKUP($M33,FORMULAS!$O$12:$P$13,2,FALSE)*N33 -> 0 | P33: =VLOOKUP($M33,FORMULAS!$O$12:$Q$13,3,FALSE)*N33 -> 0 | Q33: =VLOOKUP($M33,FORMULAS!$O$12:$R$13,4,FALSE)*N33 -> 0 | U33: =M33 -> Libre consumo | V33: =N33 -> 0
L34: Lácteos | M34: Descremados - bajos en grasas | N34: 0 | O34: =VLOOKUP($M34,FORMULAS!$O$14:$P$18,2,FALSE)*N34 -> 0 | P34: =VLOOKUP($M34,FORMULAS!$O$14:$Q$18,3,FALSE)*N34 -> 0 | Q34: =VLOOKUP($M34,FORMULAS!$O$14:$R$18,4,FALSE)*N34 -> 0 | T34: Lácteos | U34: =M34 -> Descremados - bajos en grasas | V34: =N34 -> 0
M35: Semidescremados - medios en grasas | N35: 1 | O35: =VLOOKUP($M35,FORMULAS!$O$14:$P$18,2,FALSE)*N35 -> 11 | P35: =VLOOKUP($M35,FORMULAS!$O$14:$Q$18,3,FALSE)*N35 -> 8 | Q35: =VLOOKUP($M35,FORMULAS!$O$14:$R$18,4,FALSE)*N35 -> 4 | U35: =M35 -> Semidescremados - medios en grasas | V35: =N35 -> 1
L36: Carnes, pescados y huevos | M36: Medios en grasas | N36: 0 | O36: =VLOOKUP($M36,FORMULAS!$O$19:$P$22,2,FALSE)*N36 -> 0 | P36: =VLOOKUP($M36,FORMULAS!$O$19:$Q$22,3,FALSE)*N36 -> 0 | Q36: =VLOOKUP($M36,FORMULAS!$O$19:$R$22,4,FALSE)*N36 -> 0 | T36: Carnes, pescados y huevos | U36: =M36 -> Medios en grasas | V36: =N36 -> 0
M37: Bajos en grasas | N37: 0 | O37: =VLOOKUP($M37,FORMULAS!$O$19:$P$22,2,FALSE)*N37 -> 0 | P37: =VLOOKUP($M37,FORMULAS!$O$19:$Q$22,3,FALSE)*N37 -> 0 | Q37: =VLOOKUP($M37,FORMULAS!$O$19:$R$22,4,FALSE)*N37 -> 0 | U37: =M37 -> Bajos en grasas | V37: =N37 -> 0
M38: Embutidos | N38: 0 | O38: =VLOOKUP($M38,FORMULAS!$O$19:$P$22,2,FALSE)*N38 -> 0 | P38: =VLOOKUP($M38,FORMULAS!$O$19:$Q$22,3,FALSE)*N38 -> 0 | Q38: =VLOOKUP($M38,FORMULAS!$O$19:$R$22,4,FALSE)*N38 -> 0 | U38: =M38 -> Embutidos | V38: =N38 -> 0
L39: Leguminosas | M39: Leguminosas | N39: 0 | O39: =VLOOKUP($M39,FORMULAS!$O$23:$P$23,2,FALSE)*N39 -> 0 | P39: =VLOOKUP($M39,FORMULAS!$O$23:$Q$23,3,FALSE)*N39 -> 0 | Q39: =VLOOKUP($M39,FORMULAS!$O$23:$R$23,4,FALSE)*N39 -> 0 | T39: Leguminosas | U39: =M39 -> Leguminosas | V39: =N39 -> 0
L40: Grasas y frutos secos | M40: Altos en grasas y bajos en CHO | N40: 0.5 | O40: =VLOOKUP($M40,FORMULAS!$O$24:$P$27,2,FALSE)*N40 -> 4 | P40: =VLOOKUP($M40,FORMULAS!$O$24:$Q$27,3,FALSE)*N40 -> 2 | Q40: =VLOOKUP($M40,FORMULAS!$O$24:$R$27,4,FALSE)*N40 -> 5 | T40: Grasas y frutos secos | U40: =M40 -> Altos en grasas y bajos en CHO | V40: =N40 -> 0.5
...

Sheet HOMBRE
A1: HOMBRE
A2: Peso kg | B2: 85
A3: Talla | B3: 170 | L3: DESAYUNO | T3: DESAYUNO
A4: IMC | B4: =B2/((B3*0.01)^2) -> 29.411765 | E4: Nutrimento | F4: % | G4: Energía Kcal | H4: Gramos | O4: CHO (g) | P4: Prot (g) | Q4: Grasas (g) | W4: LUNES | Y4: MARTES | AA4: MIERCOLES | AC4: JUEVES | AE4: VIERNES
A5: Edad | B5: 45 | E5: CHO | F5: =100-F6-F7 -> 46.456653 | G5: =(C10*F5)/100 -> 1022.1625 | H5: =G5/4 -> 255.54062 | L5: Grupo de alimento | M5: Subgrupo | N5: # de raciones de intercambio | O5: =G15 -> 51.108125 | P5: =H15 -> 20.4 | Q5: =I15 -> 17.113056 | T5: Grupo de alimento | U5: Subgrupo | V5: # | W5: Descripción (alimento) | X5: Cantidad | Y5: Descripción (alimento) | Z5: Cantidad | AA5: Descripción (alimento) | AB5: Cantidad | AC5: Descripción (alimento) | AD5: Cantidad | AE5: Descripción (alimento) | AF5: Cantidad
A6: Kcal Extra | B6: 0 | E6: Proteínas | F6: =(G6*100)/C10 -> 18.543347 | G6: =H6*4 -> 408 | H6: =B2*B14 -> 102 | L6: Cereales, tuberculos y plátanos | M6: Medios en CHO y medios en grasas | N6: 0.75 | O6: =VLOOKUP($M6,FORMULAS!$O$6:$P$8,2,FALSE)*N6 -> 15 | P6: =VLOOKUP($M6,FORMULAS!$O$6:$Q$8,3,FALSE)*N6 -> 1.5 | Q6: =VLOOKUP($M6,FORMULAS!$O$6:$R$8,4,FALSE)*N6 -> 4.5 | T6: Cereales, tuberculos y plátanos | U6: =M6 -> Medios en CHO y medios en grasas | V6: =N6 -> 0.75
E7: Lípidos | F7: 35 | G7: =(C10*F7)/100 -> 770.0875 | H7: =G7/9 -> 85.565278 | M7: Medios en CHO y bajos en grasas | N7: 0 | O7: =VLOOKUP($M7,FORMULAS!$O$6:$P$8,2,FALSE)*N7 -> 0 | P7: =VLOOKUP($M7,FORMULAS!$O$6:$Q$8,3,FALSE)*N7 -> 0 | Q7: =VLOOKUP($M7,FORMULAS!$O$6:$R$8,4,FALSE)*N7 -> 0 | U7: =M7 -> Medios en CHO y bajos en grasas | V7: =N7 -> 0
E8: Total | F8: =SUM(F5:F7) -> 100 | G8: =SUM(G5:G7) -> 2200.25 | H8: =SUM(H5:H7) -> 443.1059 | L8: Frutas | M8: Bajas en CHO | N8: 1 | O8: =VLOOKUP($M8,FORMULAS!$O$9:$P$11,2,FALSE)*N8 -> 10 | P8: =VLOOKUP($M8,FORMULAS!$O$9:$Q$11,3,FALSE)*N8 -> 1 | Q8: =VLOOKUP($M8,FORMULAS!$O$9:$R$11,4,FALSE)*N8 -> 0 | T8: Frutas | U8: =M8 -> Bajas en CHO | V8: =N8 -> 1
A9: GET | M9: Bajas en CHO | N9: 0 | O9: =VLOOKUP($M9,FORMULAS!$O$9:$P$11,2,FALSE)*N9 -> 0 | P9: =VLOOKUP($M9,FORMULAS!$O$9:$Q$11,3,FALSE)*N9 -> 0 | Q9: =VLOOKUP($M9,FORMULAS!$O$9:$R$11,4,FALSE)*N9 -> 0 | U9: =M9 -> Bajas en CHO | V9: =N9 -> 0
A10: Hombre | B10: mifflin | C10: =FORMULAS!J15+B6 -> 2200.25 | L10: Vegetales | M10: Bajos en CHO | N10: 0 | O10: =VLOOKUP($M10,FORMULAS!$O$12:$P$13,2,FALSE)*N10 -> 0 | P10: =VLOOKUP($M10,FORMULAS!$O$12:$Q$13,3,FALSE)*N10 -> 0 | Q10: =VLOOKUP($M10,FORMULAS!$O$12:$R$13,4,FALSE)*N10 -> 0 | T10: Vegetales | U10: =M10 -> Bajos en CHO | V10: =N10 -> 0
M11: Libre consumo | N11: 0 | O11: =VLOOKUP($M11,FORMULAS!$O$12:$P$13,2,FALSE)*N11 -> 0 | P11: =VLOOKUP($M11,FORMULAS!$O$12:$Q$13,3,FALSE)*N11 -> 0 | Q11: =VLOOKUP($M11,FORMULAS!$O$12:$R$13,4,FALSE)*N11 -> 0 | U11: =M11 -> Libre consumo | V11: =N11 -> 0
E12: Distribución de Alimentos | L12: Lácteos | M12: Enteros - altos en grasas | N12: 0 | O12: =VLOOKUP($M12,FORMULAS!$O$14:$P$18,2,FALSE)*N12 -> 0 | P12: =VLOOKUP($M12,FORMULAS!$O$14:$Q$18,3,FALSE)*N12 -> 0 | Q12: =VLOOKUP($M12,FORMULAS!$O$14:$R$18,4,FALSE)*N12 -> 0 | T12: Lácteos | U12: =M12 -> Enteros - altos en grasas | V12: =N12 -> 0
A13: Proteína g/kg/día | E13: # de fraccionamiento | I13: 5 | M13: Descremados y altos en CHO | N13: 0 | O13: =VLOOKUP($M13,FORMULAS!$O$14:$P$18,2,FALSE)*N13 -> 0 | P13: =VLOOKUP($M13,FORMULAS!$O$14:$Q$18,3,FALSE)*N13 -> 0 | Q13: =VLOOKUP($M13,FORMULAS!$O$14:$R$18,4,FALSE)*N13 -> 0 | U13: =M13 -> Descremados y altos en CHO | V13: =N13 -> 0
